{"total_count": 100, "incomplete_results": false, "items": [{"url": "https://api.github.com/repos/microsoft/azure-devops-python-api/issues/467", "repository_url": "https://api.github.com/repos/microsoft/azure-devops-python-api", "labels_url": "https://api.github.com/repos/microsoft/azure-devops-python-api/issues/467/labels{/name}", "comments_url": "https://api.github.com/repos/microsoft/azure-devops-python-api/issues/467/comments", "events_url": "https://api.github.com/repos/microsoft/azure-devops-python-api/issues/467/events", "html_url": "https://github.com/microsoft/azure-devops-python-api/issues/467", "id": 1855627299, "node_id": "I_kwDOBmuGes5umqAj", "number": 467, "title": "Getting started code throws error in notebook", "user": {"login": "uncheckederror", "id": 11726956, "node_id": "MDQ6VXNlcjExNzI2OTU2", "avatar_url": "https://avatars.githubusercontent.com/u/11726956?v=4", "gravatar_id": "", "url": "https://api.github.com/users/uncheckederror", "html_url": "https://github.com/uncheckederror", "followers_url": "https://api.github.com/users/uncheckederror/followers", "following_url": "https://api.github.com/users/uncheckederror/following{/other_user}", "gists_url": "https://api.github.com/users/uncheckederror/gists{/gist_id}", "starred_url": "https://api.github.com/users/uncheckederror/starred{/owner}{/repo}", "subscriptions_url": "https://api.github.com/users/uncheckederror/subscriptions", "organizations_url": "https://api.github.com/users/uncheckederror/orgs", "repos_url": "https://api.github.com/users/uncheckederror/repos", "events_url": "https://api.github.com/users/uncheckederror/events{/privacy}", "received_events_url": "https://api.github.com/users/uncheckederror/received_events", "type": "User", "site_admin": false}, "labels": [], "state": "open", "locked": false, "assignee": null, "assignees": [], "milestone": null, "comments": 2, "created_at": "2023-08-17T20:01:53Z", "updated_at": "2023-09-14T06:08:26Z", "closed_at": null, "author_association": "NONE", "active_lock_reason": null, "body": "Running this code from the Getting Started section of the readme.md:\r\n\r\n```\r\nfrom azure.devops.connection import Connection\r\nfrom msrest.authentication import BasicAuthentication\r\nimport pprint\r\n\r\n# Fill in with your personal access token and org URL\r\npersonal_access_token = '**removed**'\r\norganization_url = 'https://**notthedevdomain**.visualstudio.com/'\r\n\r\n# Create a connection to the org\r\ncredentials = BasicAuthentication('', personal_access_token)\r\nconnection = Connection(base_url=organization_url, creds=credentials)\r\n\r\n# Get a client (the \"core\" client provides access to projects, teams, etc)\r\ncore_client = connection.clients.get_core_client()\r\n\r\n# Get the first page of projects\r\nget_projects_response = core_client.get_projects()\r\nindex = 0\r\nwhile get_projects_response is not None:\r\n    for project in get_projects_response.value:\r\n        pprint.pprint(\"[\" + str(index) + \"] \" + project.name)\r\n        index += 1\r\n    if get_projects_response.continuation_token is not None and get_projects_response.continuation_token != \"\":\r\n        # Get the next page of projects\r\n        get_projects_response = core_client.get_projects(continuation_token=get_projects_response.continuation_token)\r\n    else:\r\n        # All projects have been retrieved\r\n        get_projects_response = None\r\n```\r\n\r\nProduces this error:\r\n```\r\n---------------------------------------------------------------------------\r\nAttributeError                            Traceback (most recent call last)\r\n/tmp/ipykernel_19/1987585116.py in <cell line: 19>()\r\n     18 index = 0\r\n     19 while get_projects_response is not None:\r\n---> 20     for project in get_projects_response.value:\r\n     21         pprint.pprint(\"[\" + str(index) + \"] \" + project.name)\r\n     22         index += 1\r\n\r\nAttributeError: 'list' object has no attribute 'value'\r\n```\r\n\r\nIn this environment:\r\n\r\n> ArcGIS Notebooks\r\n> Server Information:\r\n> You are using Jupyter notebook.\r\n> \r\n> The version of the notebook server is: 6.4.12\r\n> The server is running on this version of Python:\r\n> Python 3.9.16 (main, Jan 11 2023, 16:05:54) \r\n> [GCC 11.2.0]\r\n> \r\n> Current Kernel Information:\r\n> Python 3.9.16 (main, Jan 11 2023, 16:05:54) \r\n> Type 'copyright', 'credits' or 'license' for more information\r\n> IPython 7.34.0 -- An enhanced Interactive Python. Type '?' for help.\r\n\r\nTo solve this error you have to remove the \".value\" on get_projects_response on line 20.\r\n\r\n```\r\nwhile get_projects_response is not None:\r\n    for project in get_projects_response:\r\n```\r\nrather than the current:\r\n\r\n```\r\nwhile get_projects_response is not None:\r\n    for project in get_projects_response.value:\r\n```\r\nWould be cool if the readme.md could get updated to improve the onboarding experience for this package.", "reactions": {"url": "https://api.github.com/repos/microsoft/azure-devops-python-api/issues/467/reactions", "total_count": 0, "+1": 0, "-1": 0, "laugh": 0, "hooray": 0, "confused": 0, "heart": 0, "rocket": 0, "eyes": 0}, "timeline_url": "https://api.github.com/repos/microsoft/azure-devops-python-api/issues/467/timeline", "performed_via_github_app": null, "state_reason": null, "score": 1.0}]}